a = 2;
b = 3;

bad_init = || {
    a + b = 5;
};

assert(
    (protected_call(bad_init)).err,
    "a + b = 5 should throw."
);
